Workbook

Sheet Akun
A1: KODE | B1: NAMA AKUN | C1: KATEGORI | D1: KELOMPOK KAS | E1: KELOMPOK Nrc /RL | F1: TIPE | G1: KODE
A2: 101 | B2: Kas | C2: Aktifa Lancar | D2: KAS | E2: Kas | F2: Debet | G2: =A2 -> 101
A3: 102 | B3: Bank | C3: Aktifa Lancar | D3: BANK | E3: Bank | F3: Debet | G3: =A3 -> 102
A4: 103 | B4: Piutang Siswa | C4: Aktifa Lancar | D4: Penjualan & Penerimaan Piutang Siswa | E4: Piutang | F4: Debet | G4: =A4 -> 103
A5: 104 | B5: Piutang Lain-Lain | C5: Aktifa Lancar | D5: PENERIMAAN PEMBAYARAN PIUTANG | E5: Piutang | F5: Debet | G5: =A5 -> 104
A6: 105 | B6: Piutang Periode Sebelumnya | C6: Aktifa Lancar | E6: Piutang Periode Sebelumnya | F6: Debet | G6: =A6 -> 105
A7: 106 | B7: Biaya Dibayar Dimuka | C7: Aktifa Lancar | E7: Biaya Dibayar Dimuka | F7: Debet | G7: =A7 -> 106
A8: 107 | B8: Tanah | C8: Aktifa Tetap | E8: Tanah | F8: Debet | G8: =A8 -> 107
A9: 108 | B9: Gedung | C9: Aktifa Tetap | E9: Gedung | F9: Debet | G9: =A9 -> 108
A10: 109 | B10: Kendaraan | C10: Aktifa Tetap | E10: Kendaraan | F10: Debet | G10: =A10 -> 109
A11: 110 | B11: Peralatan Kantor | C11: Aktifa Tetap | E11: Peralatan Kantor | F11: Debet | G11: =A11 -> 110
A12: 111 | B12: Akumulasi Penyusutan Aktifa Tetap | C12: Aktifa Tetap | E12: Akumulasi Penyusutan Aktifa Tetap | F12: Debet | G12: =A12 -> 111
A13: 200 | B13: Hutang Usaha | C13: Kewajiban | D13: Hutang Usaha | E13: Hutang Usaha | F13: Kredit | G13: =A13 -> 200
A14: 201 | B14: Hutang Lancar | C14: Kewajiban | D14: Hutang Lancar | E14: Hutang Lancar | F14: Kredit | G14: =A14 -> 201
A15: 300 | B15: Setoran Modal Pemilik | C15: Modal | D15: Setoran Modal | E15: Setoran Modal Pemilik | F15: Kredit | G15: =A15 -> 300
A16: 301 | B16: Modal Awal | C16: Modal | D16: Modal Awal | E16: Modal Awal | F16: Kredit | G16: =A16 -> 301
A17: 302 | B17: Laba (Rugi) Periode Sebelumnya | C17: Modal | D17: Laba (Rugi) Periode Sebelumnya | E17: Laba (Rugi) Periode Sebelumnya | F17: Kredit | G17: =A17 -> 302
A18: 303 | B18: Laba (Rugi) Periode Berjalan | C18: Modal | D18: Laba (Rugi) Periode Berjalan | E18: Laba (Rugi) Periode Berjalan | F18: Kredit | G18: =A18 -> 303
A19: 304 | B19: Prive | C19: Modal | E19: Prive | F19: Kredit | G19: =A19 -> 304
A20: 400 | B20: Penerimaan Dana Pendaftaran | C20: Pendapatan | D20: Penerimaan Dana Pendaftaran | E20: Penerimaan Dana Pendaftaran | F20: Kredit | G20: =A20 -> 400
A21: 401 | B21: Penerimaan Uang Gedung | C21: Pendapatan | D21: Penerimaan Uang Gedung | E21: Penerimaan Uang Gedung | F21: Kredit | G21: =A21 -> 401
A22: 402 | B22: Penerimaan Uang Kegiatan | C22: Pendapatan | D22: Penerimaan Uang Kegiatan | E22: Penerimaan Uang Kegiatan | F22: Kredit | G22: =A22 -> 402
A23: 403 | B23: Penerimaan Uang Seragam | C23: Pendapatan | D23: Penerimaan Uang Seragam | E23: Penerimaan Uang Seragam | F23: Kredit | G23: =A23 -> 403
A24: 404 | B24: Penerimaan Uang ATK | C24: Pendapatan | D24: Penerimaan Uang ATK | E24: Penerimaan Uang ATK | F24: Kredit | G24: =A24 -> 404
A25: 405 | B25: Penerimaan Uang SPP | C25: Pendapatan | D25: Penerimaan Uang SPP | E25: Penerimaan Uang SPP | F25: Kredit | G25: =A25 -> 405
A26: 406 | B26: Pendapatan Lain-Lain | C26: Pendapatan | D26: Pendapatan Lain-Lain | E26: Pendapatan Lain-Lain | F26: Kredit | G26: =A26 -> 406
A27: 407 | B27: Penerimaan piutang siswa | C27: Pendapatan | D27: Penerimaan piutang siswa | E27: Penerimaan piutang siswa | F27: Kredit | G27: =A27 -> 407
A28: 500 | B28: Biaya Gaji | C28: Biaya SPP | D28: Biaya Gaji | E28: Biaya Gaji | F28: Debet | G28: =A28 -> 500
A29: 501 | B29: Biaya Tunjangan | C29: Biaya SPP | D29: Biaya Tunjangan | E29: Biaya Tunjangan | F29: Debet | G29: =A29 -> 501
A30: 502 | B30: Biaya ATK Kantor | C30: Biaya SPP | D30: Biaya ATK Kantor | E30: Biaya ATK Kantor | F30: Debet | G30: =A30 -> 502
A31: 503 | B31: Biaya UKS | C31: Biaya SPP | D31: Biaya Tunjangan Lain-Lain | E31: Biaya Tunjangan Lain-Lain | F31: Debet | G31: =A31 -> 503
... A50: 522 | B50: Pajak | C50: Biaya Gedung | D50: Biaya Gedung | E50: Biaya Gedung | F50: Debet | G50: =A50 -> 522
A52: TOTAL | G52: =A52 -> TOTAL
A53: CASHFLOW | G53: =A53 -> CASHFLOW
A54: SELISIH | G54: =A54 -> SELISIH

Sheet Aktiva Tetap

Sheet Rekap
A1: KODE | B1: NAMA AKUN | C1: NERACA SALDO | E1: PENYESUAIAN | G1: NS SETELAH PENYESUAIAN | I1: LABA RUGI | K1: NERACA
C2: DEBET | D2: KREDIT | E2: DEBET | F2: KREDIT | G2: DEBET | H2: KREDIT | I2: DEBET | J2: KREDIT | K2: DEBET | L2: KREDIT
A3: =Akun!A2 -> 101 | B3: =Akun!B2 -> Kas | C3: =SUM(Cashflow!E:E)-SUM(Cashflow!F:F) -> 0 | G3: =C3-E3 -> 0 | H3: =D3-F3 -> 0 | I3: =IF(A3>=400,G3,0) -> 0 | J3: =IF(A3>=400,H3,0) -> 0 | K3: =IF(A3<400,G3,0) -> 0 | L3: =IF(A3<400,H3,0) -> 0
A4: =Akun!A3 -> 102 | B4: =Akun!B3 -> Bank | C4: =SUMIF(Cashflow!D:D,Rekap!A4,Cashflow!F:F)-SUMIF(Cashflow!D:D,Rekap!A4,Cashflow!E:E) -> 0 | G4: =C4-E4 -> 0 | H4: =D4-F4 -> 0 | I4: =IF(A4>=400,G4,0) -> 0 | J4: =IF(A4>=400,H4,0) -> 0 | K4: =IF(A4<400,G4,0) -> 0 | L4: =IF(A4<400,H4,0) -> 0
A5: =Akun!A4 -> 103 | B5: =Akun!B4 -> Piutang Siswa | C5: ='Data Siswa'!AC100 -> 0 | G5: =C5-E5 -> 0 | H5: =D5-F5 -> 0 | I5: =IF(A5>=400,G5,0) -> 0 | J5: =IF(A5>=400,H5,0) -> 0 | K5: =IF(A5<400,G5,0) -> 0 | L5: =IF(A5<400,H5,0) -> 0
A6: =Akun!A5 -> 104 | B6: =Akun!B5 -> Piutang Lain-Lain | C6: =SUMIF(Cashflow!D:D,Rekap!A6,Cashflow!F:F)-SUMIF(Cashflow!D:D,Rekap!A6,Cashflow!E:E) -> 0 | G6: =C6-E6 -> 0 | H6: =D6-F6 -> 0 | I6: =IF(A6>=400,G6,0) -> 0 | J6: =IF(A6>=400,H6,0) -> 0 | K6: =IF(A6<400,G6,0) -> 0 | L6: =IF(A6<400,H6,0) -> 0
A7: =Akun!A6 -> 105 | B7: =Akun!B6 -> Piutang Periode Sebelumnya | G7: =C7-E7 -> 0 | H7: =D7-F7 -> 0 | I7: =IF(A7>=400,G7,0) -> 0 | J7: =IF(A7>=400,H7,0) -> 0 | K7: =IF(A7<400,G7,0) -> 0 | L7: =IF(A7<400,H7,0) -> 0
A8: =Akun!A7 -> 106 | B8: =Akun!B7 -> Biaya Dibayar Dimuka | G8: =C8-E8 -> 0 | H8: =D8-F8 -> 0 | I8: =IF(A8>=400,G8,0) -> 0 | J8: =IF(A8>=400,H8,0) -> 0 | K8: =IF(A8<400,G8,0) -> 0 | L8: =IF(A8<400,H8,0) -> 0
A9: =Akun!A8 -> 107 | B9: =Akun!B8 -> Tanah | G9: =C9-E9 -> 0 | H9: =D9-F9 -> 0 | I9: =IF(A9>=400,G9,0) -> 0 | J9: =IF(A9>=400,H9,0) -> 0 | K9: =IF(A9<400,G9,0) -> 0 | L9: =IF(A9<400,H9,0) -> 0
A10: =Akun!A9 -> 108 | B10: =Akun!B9 -> Gedung | G10: =C10-E10 -> 0 | H10: =D10-F10 -> 0 | I10: =IF(A10>=400,G10,0) -> 0 | J10: =IF(A10>=400,H10,0) -> 0 | K10: =IF(A10<400,G10,0) -> 0 | L10: =IF(A10<400,H10,0) -> 0
A11: =Akun!A10 -> 109 | B11: =Akun!B10 -> Kendaraan | G11: =C11-E11 -> 0 | H11: =D11-F11 -> 0 | I11: =IF(A11>=400,G11,0) -> 0 | J11: =IF(A11>=400,H11,0) -> 0 | K11: =IF(A11<400,G11,0) -> 0 | L11: =IF(A11<400,H11,0) -> 0
A12: =Akun!A11 -> 110 | B12: =Akun!B11 -> Peralatan Kantor | G12: =C12-E12 -> 0 | H12: =D12-F12 -> 0 | I12: =IF(A12>=400,G12,0) -> 0 | J12: =IF(A12>=400,H12,0) -> 0 | K12: =IF(A12<400,G12,0) -> 0 | L12: =IF(A12<400,H12,0) -> 0
A13: =Akun!A12 -> 111 | B13: =Akun!B12 -> Akumulasi Penyusutan Aktifa Tetap | G13: =C13-E13 -> 0 | H13: =D13-F13 -> 0 | I13: =IF(A13>=400,G13,0) -> 0 | J13: =IF(A13>=400,H13,0) -> 0 | K13: =IF(A13<400,G13,0) -> 0 | L13: =IF(A13<400,H13,0) -> 0
A14: =Akun!A13 -> 200 | B14: =Akun!B13 -> Hutang Usaha | D14: =SUMIF(Cashflow!D:D,A14,Cashflow!E:E) -> 0 | G14: =C14-E14 -> 0 | H14: =D14-F14 -> 0 | I14: =IF(A14>=400,G14,0) -> 0 | J14: =IF(A14>=400,H14,0) -> 0 | K14: =IF(A14<400,G14,0) -> 0 | L14: =IF(A14<400,H14,0) -> 0
A15: =Akun!A14 -> 201 | B15: =Akun!B14 -> Hutang Lancar | D15: =SUMIF(Cashflow!D:D,A15,Cashflow!E:E) -> 0 | G15: =C15-E15 -> 0 | H15: =D15-F15 -> 0 | I15: =IF(A15>=400,G15,0) -> 0 | J15: =IF(A15>=400,H15,0) -> 0 | K15: =IF(A15<400,G15,0) -> 0 | L15: =IF(A15<400,H15,0) -> 0
A16: =Akun!A15 -> 300 | B16: =Akun!B15 -> Setoran Modal Pemilik | D16: =SUMIF(Cashflow!D:D,A16,Cashflow!E:E) -> 0 | G16: =C16-E16 -> 0 | H16: =D16-F16 -> 0 | I16: =IF(A16>=400,G16,0) -> 0 | J16: =IF(A16>=400,H16,0) -> 0 | K16: =IF(A16<400,G16,0) -> 0 | L16: =IF(A16<400,H16,0) -> 0
A17: =Akun!A16 -> 301 | B17: =Akun!B16 -> Modal Awal | D17: =SUMIF(Cashflow!D:D,A17,Cashflow!E:E) -> 0 | G17: =C17-E17 -> 0 | H17: =D17-F17 -> 0 | I17: =IF(A17>=400,G17,0) -> 0 | J17: =IF(A17>=400,H17,0) -> 0 | K17: =IF(A17<400,G17,0) -> 0 | L17: =IF(A17<400,H17,0) -> 0
A18: =Akun!A17 -> 302 | B18: =Akun!B17 -> Laba (Rugi) Periode Sebelumnya | D18: =SUMIF(Cashflow!D:D,A18,Cashflow!E:E) -> 0 | G18: =C18-E18 -> 0 | H18: =D18-F18 -> 0 | I18: =IF(A18>=400,G18,0) -> 0 | J18: =IF(A18>=400,H18,0) -> 0 | K18: =IF(A18<400,G18,0) -> 0 | L18: =IF(A18<400,H18,0) -> 0
A19: =Akun!A18 -> 303 | B19: =Akun!B18 -> Laba (Rugi) Periode Berjalan | D19: =SUMIF(Cashflow!D:D,A19,Cashflow!E:E) -> 0 | G19: =C19-E19 -> 0 | H19: =D19-F19 -> 0 | I19: =IF(A19>=400,G19,0) -> 0 | J19: =IF(A19>=400,H19,0) -> 0 | K19: =IF(A19<400,G19,0) -> 0 | L19: =I54 -> 0
A20: =Akun!A19 -> 304 | B20: =Akun!B19 -> Prive | D20: =SUMIF(Cashflow!D:D,A20,Cashflow!E:E) -> 0 | G20: =C20-E20 -> 0 | H20: =D20-F20 -> 0 | I20: =IF(A20>=400,G20,0) -> 0 | J20: =IF(A20>=400,H20,0) -> 0 | K20: =IF(A20<400,G20,0) -> 0 | L20: =IF(A20<400,H20,0) -> 0
A21: =Akun!A20 -> 400 | B21: =Akun!B20 -> Penerimaan Dana Pendaftaran | D21: ='Data Siswa'!F100 -> 0 | G21: =C21-E21 -> 0 | H21: =D21-F21 -> 0 | I21: =IF(A21>=400,G21,0) -> 0 | J21: =IF(A21>=400,H21,0) -> 0 | K21: =IF(A21<400,G21,0) -> 0 | L21: =IF(A21<400,H21,0) -> 0
A22: =Akun!A21 -> 401 | B22: =Akun!B21 -> Penerimaan Uang Gedung | D22: ='Data Siswa'!H100 -> 0 | G22: =C22-E22 -> 0 | H22: =D22-F22 -> 0 | I22: =IF(A22>=400,G22,0) -> 0 | J22: =IF(A22>=400,H22,0) -> 0 | K22: =IF(A22<400,G22,0) -> 0 | L22: =IF(A22<400,H22,0) -> 0
A23: =Akun!A22 -> 402 | B23: =Akun!B22 -> Penerimaan Uang Kegiatan | D23: ='Data Siswa'!J100 -> 0 | G23: =C23-E23 -> 0 | H23: =D23-F23 -> 0 | I23: =IF(A23>=400,G23,0) -> 0 | J23: =IF(A23>=400,H23,0) -> 0 | K23: =IF(A23<400,G23,0) -> 0 | L23: =IF(A23<400,H23,0) -> 0
A24: =Akun!A23 -> 403 | B24: =Akun!B23 -> Penerimaan Uang Seragam | D24: ='Data Siswa'!L100 -> 0 | G24: =C24-E24 -> 0 | H24: =D24-F24 -> 0 | I24: =IF(A24>=400,G24,0) -> 0 | J24: =IF(A24>=400,H24,0) -> 0 | K24: =IF(A24<400,G24,0) -> 0 | L24: =IF(A24<400,H24,0) -> 0
A25: =Akun!A24 -> 404 | B25: =Akun!B24 -> Penerimaan Uang ATK | D25: ='Data Siswa'!N100 -> 0 | G25: =C25-E25 -> 0 | H25: =D25-F25 -> 0 | I25: =IF(A25>=400,G25,0) -> 0 | J25: =IF(A25>=400,H25,0) -> 0 | K25: =IF(A25<400,G25,0) -> 0 | L25: =IF(A25<400,H25,0) -> 0
A26: =Akun!A25 -> 405 | B26: =Akun!B25 -> Penerimaan Uang SPP | D26: ='Data Siswa'!P100+'Data Siswa'!R100+'Data Siswa'!T100+'Data Siswa'!V100+'Data Siswa'!X100+'Data Siswa'!Z100 -> 0 | G26: =C26-E26 -> 0 | H26: =D26-F26 -> 0 | I26: =IF(A26>=400,G26,0) -> 0 | J26: =IF(A26>=400,H26,0) -> 0 | K26: =IF(A26<400,G26,0) -> 0 | L26: =IF(A26<400,H26,0) -> 0
A27: =Akun!A26 -> 406 | B27: =Akun!B26 -> Pendapatan Lain-Lain | D27: =SUMIF(Cashflow!D:D,A27,Cashflow!E:E) -> 0 | G27: =C27-E27 -> 0 | H27: =D27-F27 -> 0 | I27: =IF(A27>=400,G27,0) -> 0 | J27: =IF(A27>=400,H27,0) -> 0 | K27: =IF(A27<400,G27,0) -> 0 | L27: =IF(A27<400,H27,0) -> 0
A28: =Akun!A27 -> 407 | B28: =Akun!B27 -> Penerimaan piutang siswa | D28: ='Data Siswa'!AC100 -> 0 | G28: =C28-E28 -> 0 | H28: =D28-F28 -> 0 | I28: =IF(A28>=400,G28,0) -> 0 | J28: =IF(A28>=400,H28,0) -> 0 | K28: =IF(A28<400,G28,0) -> 0 | L28: =IF(A28<400,H28,0) -> 0
A29: =Akun!A28 -> 500 | B29: =Akun!B28 -> Biaya Gaji | C29: =SUMIF(Cashflow!D:D,A29,Cashflow!F:F) -> 0 | G29: =C29-E29 -> 0 | H29: =D29-F29 -> 0 | I29: =IF(A29>=400,G29,0) -> 0 | J29: =IF(A29>=400,H29,0) -> 0 | K29: =IF(A29<400,G29,0) -> 0 | L29: =IF(A29<400,H29,0) -> 0
A30: =Akun!A29 -> 501 | B30: =Akun!B29 -> Biaya Tunjangan | C30: =SUMIF(Cashflow!D:D,A30,Cashflow!F:F) -> 0 | G30: =C30-E30 -> 0 | H30: =D30-F30 -> 0 | I30: =IF(A30>=400,G30,0) -> 0 | J30: =IF(A30>=400,H30,0) -> 0 | K30: =IF(A30<400,G30,0) -> 0 | L30: =IF(A30<400,H30,0) -> 0
A31: =Akun!A30 -> 502 | B31: =Akun!B30 -> Biaya ATK Kantor | C31: =SUMIF(Cashflow!D:D,A31,Cashflow!F:F) -> 0 | G31: =C31-E31 -> 0 | H31: =D31-F31 -> 0 | I31: =IF(A31>=400,G31,0) -> 0 | J31: =IF(A31>=400,H31,0) -> 0 | K31: =IF(A31<400,G31,0) -> 0 | L31: =IF(A31<400,H31,0) -> 0
A32: =Akun!A31 -> 503 | B32: =Akun!B31 -> Biaya UKS | C32: =SUMIF(Cashflow!D:D,A32,Cashflow!F:F) -> 0 | G32: =C32-E32 -> 0 | H32: =D32-F32 -> 0 | I32: =IF(A32>=400,G32,0) -> 0 | J32: =IF(A32>=400,H32,0) -> 0 | K32: =IF(A32<400,G32,0) -> 0 | L32: =IF(A32<400,H32,0) -> 0
A33: =Akun!A32 -> 504 | B33: =Akun!B32 -> Biaya Listrik, Internet dan Telepon | C33: =SUMIF(Cashflow!D:D,A33,Cashflow!F:F) -> 0 | G33: =C33-E33 -> 0 | H33: =D33-F33 -> 0 | I33: =IF(A33>=400,G33,0) -> 0 | J33: =IF(A33>=400,H33,0) -> 0 | K33: =IF(A33<400,G33,0) -> 0 | L33: =IF(A33<400,H33,0) -> 0
A34: =Akun!A33 -> 505 | B34: =Akun!B33 -> Biaya iuran - iuran | C34: =SUMIF(Cashflow!D:D,A34,Cashflow!F:F) -> 0 | G34: =C34-E34 -> 0 | H34: =D34-F34 -> 0 | I34: =IF(A34>=400,G34,0) -> 0 | J34: =IF(A34>=400,H34,0) -> 0 | K34: =IF(A34<400,G34,0) -> 0 | L34: =IF(A34<400,H34,0) -> 0
A35: =Akun!A34 -> 506 | B35: =Akun!B34 -> Biaya Kebersihan & Kemanan Kantor | C35: =SUMIF(Cashflow!D:D,A35,Cashflow!F:F) -> 0 | G35: =C35-E35 -> 0 | H35: =D35-F35 -> 0 | I35: =IF(A35>=400,G35,0) -> 0 | J35: =IF(A35>=400,H35,0) -> 0 | K35: =IF(A35<400,G35,0) -> 0 | L35: =IF(A35<400,H35,0) -> 0
A36: =Akun!A35 -> 507 | B36: =Akun!B35 -> Biaya bahan bakar | C36: =SUMIF(Cashflow!D:D,A36,Cashflow!F:F) -> 0 | G36: =C36-E36 -> 0 | H36: =D36-F36 -> 0 | I36: =IF(A36>=400,G36,0) -> 0 | J36: =IF(A36>=400,H36,0) -> 0 | K36: =IF(A36<400,G36,0) -> 0 | L36: =IF(A36<400,H36,0) -> 0
A37: =Akun!A36 -> 508 | B37: =Akun!B36 -> Biaya Admin bank | C37: =SUMIF(Cashflow!D:D,A37,Cashflow!F:F) -> 0 | G37: =C37-E37 -> 0 | H37: =D37-F37 -> 0 | I37: =IF(A37>=400,G37,0) -> 0 | J37: =IF(A37>=400,H37,0) -> 0 | K37: =IF(A37<400,G37,0) -> 0 | L37: =IF(A37<400,H37,0) -> 0
A38: =Akun!A37 -> 509 | B38: =Akun!B37 -> Biaya PPDB | C38: =SUMIF(Cashflow!D:D,A38,Cashflow!F:F) -> 0 | G38: =C38-E38 -> 0 | H38: =D38-F38 -> 0 | I38: =IF(A38>=400,G38,0) -> 0 | J38: =IF(A38>=400,H38,0) -> 0 | K38: =IF(A38<400,G38,0) -> 0 | L38: =IF(A38<400,H38,0) -> 0
A39: =Akun!A38 -> 510 | B39: =Akun!B38 -> Biaya Konsumsi dan Rumah tangga | C39: =SUMIF(Cashflow!D:D,A39,Cashflow!F:F) -> 0 | G39: =C39-E39 -> 0 | H39: =D39-F39 -> 0 | I39: =IF(A39>=400,G39,0) -> 0 | J39: =IF(A39>=400,H39,0) -> 0 | K39: =IF(A39<400,G39,0) -> 0 | L39: =IF(A39<400,H39,0) -> 0
A40: =Akun!A39 -> 511 | B40: =Akun!B39 -> Evaluasi Pembelajaran | C40: =SUMIF(Cashflow!D:D,A40,Cashflow!F:F) -> 0 | G40: =C40-E40 -> 0 | H40: =D40-F40 -> 0 | I40: =IF(A40>=400,G40,0) -> 0 | J40: =IF(A40>=400,H40,0) -> 0 | K40: =IF(A40<400,G40,0) -> 0 | L40: =IF(A40<400,H40,0) -> 0
...

Sheet Cover
A1: LAPORAN BULANAN
A3: AL MADEENA ISLAMIC SCHOOL CIREBON | J3: ISIKAN BULAN & TAHUNNYA SAJA | M3: = | N3: JULI | O3: 2021 | P3: 2022
A5: ="TAHUN AJARAN "&O3&" - "&P3 -> TAHUN AJARAN 2021 - 2022 | J5: CABANG | M5: : | N5: -
A7: ="PERIODE "&N3&" "&P3 -> PERIODE JULI 2022 | J7: MANAGER | M7: : | N7: MURDIYONO
J8: STAFF KEUANGAN CABANG | M8: : | N8: ANITA MERLINA
J12: JANUARI | K12: 2020 | L12: CIREBON
J13: FEBRUARI | K13: 2021
J14: MARET | K14: 2022 | L14: -
J15: APRIL | K15: 2023 | L15: -
J16: MEI | K16: 2024 | L16: -
J17: JUNI | K17: 2025
J18: JULI | K18: 2026
J19: AGUSTUS | K19: 2027
J20: SEPTEMBER | K20: 2028
J21: OKTOBER | K21: 2029
J22: NOPEMBER | K22: 2030
J23: DESEMBER | K23: 2031
J25: ANITA MERLINA
J26: -
J27: -

Sheet Laba Rugi
A1: =Neraca!B3 -> AL MADEENA ISLAMIC SCHOOL TAHUN AJARAN 2021 - 2022
A2: =Neraca!B4 -> NERACA
A3: =Neraca!B5 -> PERIODE JULI 2021
B5: NO | C5: URAIAN | D5: KATEGORI | E5: SALDO
C6: PENDAPATAN
B7: 1 | C7: =Akun!B20 -> Penerimaan Dana Pendaftaran | D7: =Akun!C20 -> Pendapatan | E7: =Rekap!J21 -> 0
B8: 2 | C8: =Akun!B21 -> Penerimaan Uang Gedung | D8: =Akun!C21 -> Pendapatan | E8: =Rekap!J22 -> 0
B9: 3 | C9: =Akun!B22 -> Penerimaan Uang Kegiatan | D9: =Akun!C22 -> Pendapatan | E9: =Rekap!J23 -> 0
B10: 4 | C10: =Akun!B23 -> Penerimaan Uang Seragam | D10: =Akun!C23 -> Pendapatan | E10: =Rekap!J24 -> 0
B11: 5 | C11: =Akun!B24 -> Penerimaan Uang ATK | D11: =Akun!C24 -> Pendapatan | E11: =Rekap!J25 -> 0
B12: 6 | C12: =Akun!B25 -> Penerimaan Uang SPP | D12: =Akun!C25 -> Pendapatan | E12: =Rekap!J26 -> 0
B13: 7 | C13: =Akun!B26 -> Pendapatan Lain-Lain | D13: =Akun!C26 -> Pendapatan | E13: =Rekap!J27 -> 0
B14: 8 | C14: =Akun!B27 -> Penerimaan piutang siswa | D14: =Akun!C27 -> Pendapatan | E14: =Rekap!J28 -> 0
C15: JUMLAH PENDAPATAN | E15: =SUM(E7:E14) -> 0
C17: BIAYA USAHA
B18: 1 | C18: =Akun!B28 -> Biaya Gaji | D18: =Akun!C28 -> Biaya SPP | E18: =Rekap!I29 -> 0
B19: 2 | C19: =Akun!B29 -> Biaya Tunjangan | D19: =Akun!C29 -> Biaya SPP | E19: =Rekap!I30 -> 0
B20: 3 | C20: =Akun!B30 -> Biaya ATK Kantor | D20: =Akun!C30 -> Biaya SPP | E20: =Rekap!I31 -> 0
B21: 4 | C21: =Akun!B31 -> Biaya UKS | D21: =Akun!C31 -> Biaya SPP | E21: =Rekap!I32 -> 0
B22: 5 | C22: =Akun!B32 -> Biaya Listrik, Internet dan Telepon | D22: =Akun!C32 -> Biaya SPP | E22: =Rekap!I33 -> 0
B23: 6 | C23: =Akun!B33 -> Biaya iuran - iuran | D23: =Akun!C33 -> Biaya SPP | E23: =Rekap!I34 -> 0
B24: 7 | C24: =Akun!B34 -> Biaya Kebersihan & Kemanan Kantor | D24: =Akun!C34 -> Biaya SPP | E24: =Rekap!I35 -> 0
B25: 8 | C25: =Akun!B35 -> Biaya bahan bakar | D25: =Akun!C35 -> Biaya SPP | E25: =Rekap!I36 -> 0
B26: 9 | C26: =Akun!B36 -> Biaya Admin bank | D26: =Akun!C36 -> Biaya SPP | E26: =Rekap!I37 -> 0
B27: 10 | C27: =Akun!B37 -> Biaya PPDB | D27: =Akun!C37 -> Biaya Pendaftaran | E27: =Rekap!I38 -> 0
B28: 11 | C28: =Akun!B38 -> Biaya Konsumsi dan Rumah tangga | D28: =Akun!C38 -> Biaya Kegiatan | E28: =Rekap!I39 -> 0
B29: 12 | C29: =Akun!B39 -> Evaluasi Pembelajaran | D29: =Akun!C39 -> Biaya Kegiatan | E29: =Rekap!I40 -> 0
... B40: 23 | C40: =Akun!B50 -> Pajak | D40: =Akun!C50 -> Biaya Gedung | E40: =Rekap!I51 -> 0
C41: JUMLAH BIAYA USAHA | E41: =SUM(E18:E40) -> 0
C43: LABA ( RUGI ) PERIODE BERJALAN | E43: =+E15-E41 -> 0

Sheet Neraca
B3: =Cashflow!A2 -> AL MADEENA ISLAMIC SCHOOL TAHUN AJARAN 2021 - 2022
B4: NERACA
B5: ="PERIODE "&Cover!$N$3&" "&Cover!$O$3 -> PERIODE JULI 2021
C8: Aktiva lancar | H8: Hutang
C9: =Akun!B2 -> Kas | E9: =Rekap!K3 -> 0 | H9: =Akun!B13 -> Hutang Usaha | I9: =Rekap!L14 -> 0
C10: =Akun!B3 -> Bank | E10: =Rekap!K4 -> 0 | H10: =Akun!B14 -> Hutang Lancar | I10: =Rekap!L15 -> 0
C11: =Akun!B4 -> Piutang Siswa | E11: =Rekap!K5 -> 0
C12: =Akun!B5 -> Piutang Lain-Lain | E12: =Rekap!K6 -> 0
C13: =Akun!B6 -> Piutang Periode Sebelumnya | E13: =Rekap!K7 -> 0
C14: =Akun!B7 -> Biaya Dibayar Dimuka | E14: =Rekap!K8 -> 0
E15: =Rekap!K9 -> 0
C16: Jumlah Aktiva Lancar | E16: =SUM(E9:E14) -> 0 | H16: Jumlah Hutang | I16: =SUM(I9:I15) -> 0
C18: Aktiva Tetap | H18: Modal
C19: =Akun!B8 -> Tanah | E19: =Rekap!K9 -> 0 | H19: =Akun!B15 -> Setoran Modal Pemilik | I19: =Rekap!L16 -> 0
C20: =Akun!B9 -> Gedung | E20: =Rekap!K10 -> 0 | H20: =Akun!B16 -> Modal Awal | I20: =Rekap!L17 -> 0
C21: =Akun!B10 -> Kendaraan | E21: =Rekap!K11 -> 0 | H21: =Akun!B17 -> Laba (Rugi) Periode Sebelumnya | I21: =Rekap!L18 -> 0
C22: =Akun!B11 -> Peralatan Kantor | E22: =Rekap!K12 -> 0 | H22: =Akun!B18 -> Laba (Rugi) Periode Berjalan | I22: ='Laba Rugi'!E43 -> 0
C23: =Akun!B12 -> Akumulasi Penyusutan Aktifa Tetap | E23: =Rekap!K13 -> 0 | H23: =Akun!B19 -> Prive | I23: =Rekap!L20 -> 0
C26: Jumlah Aktiva Tetap | E26: =SUM(E19:E24) -> 0 | H26: Jumlah Modal | I26: =SUM(I19:I23) -> 0
L29: ANGKA DIBAWAH INI HARUS BERNILAI "0"
C30: TOTAL ALTIVA | E30: =+E16+E26 -> 0 | H30: TOTAL PASIVA | I30: =+I16+I26 -> 0 | N30: =E30-I30 -> 0
H33: CIREBON, 01 JANUARI 2022
C34: MENGETAHUI, | H34: AL MADEENA ISLAMIC SCHOOL CIREBON
C39: ='Rekap Siswa'!B19 -> MURDIYONO | H39: ='Rekap Siswa'!F19 -> ANITA MERLINA
C40: MANAGER | H40: STAFF KEUANGAN

Sheet Cashflow
A1: BUKU KAS DAN BANK HARIAN
A2: ='Data Siswa'!A2:AD2 -> AL MADEENA ISLAMIC SCHOOL TAHUN AJARAN 2021 - 2022
A3: ='Data Siswa'!A3 -> PERIODE JULI 2022
A6: Tanggal | B6: Uraian | C6: Nama Akun | D6: No Akun | E6: Debet | F6: Kredit | G6: Saldo
G8: 0 | I8: =Akun!B2 -> Kas
G9: =IF(AND(E9="",F9=""),"",(G8+E9)-F9) | I9: =Akun!B3 -> Bank
G10: =IF(AND(E10="",F10=""),"",(G9+E10)-F10) | I10: =Akun!B4 -> Piutang Siswa
G11: =IF(AND(E11="",F11=""),"",(G10+E11)-F11) | I11: =Akun!B5 -> Piutang Lain-Lain
G12: =IF(AND(E12="",F12=""),"",(G11+E12)-F12) | I12: =Akun!B6 -> Piutang Periode Sebelumnya
G13: =IF(AND(E13="",F13=""),"",(G12+E13)-F13) | I13: =Akun!B7 -> Biaya Dibayar Dimuka
G14: =IF(AND(E14="",F14=""),"",(G13+E14)-F14) | I14: =Akun!B8 -> Tanah
G15: =IF(AND(E15="",F15=""),"",(G14+E15)-F15) | I15: =Akun!B9 -> Gedung
G16: =IF(AND(E16="",F16=""),"",(G15+E16)-F16) | I16: =Akun!B10 -> Kendaraan
G17: =IF(AND(E17="",F17=""),"",(G16+E17)-F17) | I17: =Akun!B11 -> Peralatan Kantor
G18: =IF(AND(E18="",F18=""),"",(G17+E18)-F18) | I18: =Akun!B12 -> Akumulasi Penyusutan Aktifa Tetap
G19: =IF(AND(E19="",F19=""),"",(G18+E19)-F19) | I19: =Akun!B13 -> Hutang Usaha
G20: =IF(AND(E20="",F20=""),"",(G19+E20)-F20) | I20: =Akun!B14 -> Hutang Lancar
... G55: =IF(AND(E55="",F55=""),"",(G54+E55)-F55) | I55: =Akun!B49 -> Biaya ATK Siswa
G56: =IF(AND(E56="",F56=""),"",(G55+E56)-F56)
G57: =IF(AND(E57="",F57=""),"",(G56+E57)-F57)
G58: =IF(AND(E58="",F58=""),"",(G57+E58)-F58)
G59: =IF(AND(E59="",F59=""),"",(G58+E59)-F59)
G60: =IF(AND(E60="",F60=""),"",(G59+E60)-F60)
G61: =IF(AND(E61="",F61=""),"",(G60+E61)-F61)
G62: =IF(AND(E62="",F62=""),"",(G61+E62)-F62)
G63: =IF(AND(E63="",F63=""),"",(G62+E63)-F63)
G64: =IF(AND(E64="",F64=""),"",(G63+E64)-F64)
G65: =IF(AND(E65="",F65=""),"",(G64+E65)-F65)
G66: =IF(AND(E66="",F66=""),"",(G65+E66)-F66)
G67: =IF(AND(E67="",F67=""),"",(G66+E67)-F67)
... G143: =IF(AND(E143="",F143=""),"",(G142+E143)-F143)
G144: =IF(AND(E144="",F144=""),"",(G143+E144)-F144) | H144: 83556000
G145: =IF(AND(E145="",F145=""),"",(G144+E145)-F145)
G146: =IF(AND(E146="",F146=""),"",(G145+E146)-F146)
G147: =IF(AND(E147="",F147=""),"",(G146+E147)-F147)
G148: =IF(AND(E148="",F148=""),"",(G147+E148)-F148)
G149: =IF(AND(E149="",F149=""),"",(G148+E149)-F149)
G150: =IF(AND(E150="",F150=""),"",(G149+E150)-F150)
G151: =IF(AND(E151="",F151=""),"",(G150+E151)-F151)
G152: =IF(AND(E152="",F152=""),"",(G151+E152)-F152)
...

Sheet Biaya Siswa
A1: RINCIAN BIAYA
A2: ="AL MADEENA ISLAMIC SCHOOL "& Cover!A5 -> AL MADEENA ISLAMIC SCHOOL TAHUN AJARAN 2021 - 2022
A3: =Cover!A7 -> PERIODE JULI 2022
A6: NO | B6: NAMA | C6: TGL MASUK | D6: KELAS | E6: PENDAFT. | F6: GEDUNG | G6: KEGIATAN | H6: SERAGAM | I6: ATK | J6: SPP* | K6: TOTAL | L6: DISKON* | M6: BIAYA NET | O6: NO | P6: KELAS | Q6: KODE | R6: BIAYA BIAYA | X6: TOTAL
A7: 1 | E7: =IFERROR(VLOOKUP(Table3[[#This Row],[KELAS]],Q:X,2,FALSE),"") | F7: =IFERROR(VLOOKUP(Table3[[#This Row],[KELAS]],Q:X,3,FALSE),"") | G7: =IFERROR(VLOOKUP(Table3[[#This Row],[KELAS]],Q:X,4,FALSE),"") | H7: =IFERROR(VLOOKUP(Table3[[#This Row],[KELAS]],Q:X,5,FALSE),"") | I7: =IFERROR(VLOOKUP(Table3[[#This Row],[KELAS]],Q:X,6,FALSE),"") | K7: =SUM(Table3[[#This Row],[PENDAFT.]:[SPP*]]) -> 0 | M7: =Table3[[#This Row],[TOTAL]]-Table3[[#This Row],[DISKON*]] -> 0 | R7: PENDAFT. | S7: GEDUNG | T7: KEGIATAN | U7: SERAGAM | V7: ATK | W7: SPP
A8: 2 | E8: =IFERROR(VLOOKUP(Table3[[#This Row],[KELAS]],Q:X,2,FALSE),"") | F8: =IFERROR(VLOOKUP(Table3[[#This Row],[KELAS]],Q:X,3,FALSE),"") | G8: =IFERROR(VLOOKUP(Table3[[#This Row],[KELAS]],Q:X,4,FALSE),"") | H8: =IFERROR(VLOOKUP(Table3[[#This Row],[KELAS]],Q:X,5,FALSE),"") | I8: =IFERROR(VLOOKUP(Table3[[#This Row],[KELAS]],Q:X,6,FALSE),"") | K8: =SUM(Table3[[#This Row],[PENDAFT.]:[SPP*]]) -> 0 | M8: =Table3[[#This Row],[TOTAL]]-Table3[[#This Row],[DISKON*]] -> 0 | O8: 1 | P8: PLAYGROUP | Q8: PG | R8: 350000 | S8: 8000000 | T8: 2000000 | U8: 800000 | V8: 500000 | W8: 550000 | X8: =SUM(R8:W8) -> 12200000
A9: 3 | E9: =IFERROR(VLOOKUP(Table3[[#This Row],[KELAS]],Q:X,2,FALSE),"") | F9: =IFERROR(VLOOKUP(Table3[[#This Row],[KELAS]],Q:X,3,FALSE),"") | G9: =IFERROR(VLOOKUP(Table3[[#This Row],[KELAS]],Q:X,4,FALSE),"") | H9: =IFERROR(VLOOKUP(Table3[[#This Row],[KELAS]],Q:X,5,FALSE),"") | I9: =IFERROR(VLOOKUP(Table3[[#This Row],[KELAS]],Q:X,6,FALSE),"") | K9: =SUM(Table3[[#This Row],[PENDAFT.]:[SPP*]]) -> 0 | M9: =Table3[[#This Row],[TOTAL]]-Table3[[#This Row],[DISKON*]] -> 0 | O9: 2 | P9: KINDERGARTEN | Q9: KG | R9: 350000 | S9: 8000000 | T9: 2000000 | U9: 800000 | V9: 1000000 | W9: 550000 | X9: =SUM(R9:W9) -> 12700000
A10: 4 | E10: =IFERROR(VLOOKUP(Table3[[#This Row],[KELAS]],Q:X,2,FALSE),"") | F10: =IFERROR(VLOOKUP(Table3[[#This Row],[KELAS]],Q:X,3,FALSE),"") | G10: =IFERROR(VLOOKUP(Table3[[#This Row],[KELAS]],Q:X,4,FALSE),"") | H10: =IFERROR(VLOOKUP(Table3[[#This Row],[KELAS]],Q:X,5,FALSE),"") | I10: =IFERROR(VLOOKUP(Table3[[#This Row],[KELAS]],Q:X,6,FALSE),"") | K10: =SUM(Table3[[#This Row],[PENDAFT.]:[SPP*]]) -> 0 | M10: =Table3[[#This Row],[TOTAL]]-Table3[[#This Row],[DISKON*]] -> 0
A11: 5 | E11: =IFERROR(VLOOKUP(Table3[[#This Row],[KELAS]],Q:X,2,FALSE),"") | F11: =IFERROR(VLOOKUP(Table3[[#This Row],[KELAS]],Q:X,3,FALSE),"") | G11: =IFERROR(VLOOKUP(Table3[[#This Row],[KELAS]],Q:X,4,FALSE),"") | H11: =IFERROR(VLOOKUP(Table3[[#This Row],[KELAS]],Q:X,5,FALSE),"") | I11: =IFERROR(VLOOKUP(Table3[[#This Row],[KELAS]],Q:X,6,FALSE),"") | K11: =SUM(Table3[[#This Row],[PENDAFT.]:[SPP*]]) -> 0 | M11: =Table3[[#This Row],[TOTAL]]-Table3[[#This Row],[DISKON*]] -> 0
A12: 6 | E12: =IFERROR(VLOOKUP(Table3[[#This Row],[KELAS]],Q:X,2,FALSE),"") | F12: =IFERROR(VLOOKUP(Table3[[#This Row],[KELAS]],Q:X,3,FALSE),"") | G12: =IFERROR(VLOOKUP(Table3[[#This Row],[KELAS]],Q:X,4,FALSE),"") | H12: =IFERROR(VLOOKUP(Table3[[#This Row],[KELAS]],Q:X,5,FALSE),"") | I12: =IFERROR(VLOOKUP(Table3[[#This Row],[KELAS]],Q:X,6,FALSE),"") | K12: =SUM(Table3[[#This Row],[PENDAFT.]:[SPP*]]) -> 0 | M12: =Table3[[#This Row],[TOTAL]]-Table3[[#This Row],[DISKON*]] -> 0
A13: 7 | E13: =IFERROR(VLOOKUP(Table3[[#This Row],[KELAS]],Q:X,2,FALSE),"") | F13: =IFERROR(VLOOKUP(Table3[[#This Row],[KELAS]],Q:X,3,FALSE),"") | G13: =IFERROR(VLOOKUP(Table3[[#This Row],[KELAS]],Q:X,4,FALSE),"") | H13: =IFERROR(VLOOKUP(Table3[[#This Row],[KELAS]],Q:X,5,FALSE),"") | I13: =IFERROR(VLOOKUP(Table3[[#This Row],[KELAS]],Q:X,6,FALSE),"") | K13: =SUM(Table3[[#This Row],[PENDAFT.]:[SPP*]]) -> 0 | M13: =Table3[[#This Row],[TOTAL]]-Table3[[#This Row],[DISKON*]] -> 0
A14: 8 | E14: =IFERROR(VLOOKUP(Table3[[#This Row],[KELAS]],Q:X,2,FALSE),"") | F14: =IFERROR(VLOOKUP(Table3[[#This Row],[KELAS]],Q:X,3,FALSE),"") | G14: =IFERROR(VLOOKUP(Table3[[#This Row],[KELAS]],Q:X,4,FALSE),"") | H14: =IFERROR(VLOOKUP(Table3[[#This Row],[KELAS]],Q:X,5,FALSE),"") | I14: =IFERROR(VLOOKUP(Table3[[#This Row],[KELAS]],Q:X,6,FALSE),"") | K14: =SUM(Table3[[#This Row],[PENDAFT.]:[SPP*]]) -> 0 | M14: =Table3[[#This Row],[TOTAL]]-Table3[[#This Row],[DISKON*]] -> 0
A15: 9 | E15: =IFERROR(VLOOKUP(Table3[[#This Row],[KELAS]],Q:X,2,FALSE),"") | F15: =IFERROR(VLOOKUP(Table3[[#This Row],[KELAS]],Q:X,3,FALSE),"") | G15: =IFERROR(VLOOKUP(Table3[[#This Row],[KELAS]],Q:X,4,FALSE),"") | H15: =IFERROR(VLOOKUP(Table3[[#This Row],[KELAS]],Q:X,5,FALSE),"") | I15: =IFERROR(VLOOKUP(Table3[[#This Row],[KELAS]],Q:X,6,FALSE),"") | K15: =SUM(Table3[[#This Row],[PENDAFT.]:[SPP*]]) -> 0 | M15: =Table3[[#This Row],[TOTAL]]-Table3[[#This Row],[DISKON*]] -> 0
A16: 10 | E16: =IFERROR(VLOOKUP(Table3[[#This Row],[KELAS]],Q:X,2,FALSE),"") | F16: =IFERROR(VLOOKUP(Table3[[#This Row],[KELAS]],Q:X,3,FALSE),"") | G16: =IFERROR(VLOOKUP(Table3[[#This Row],[KELAS]],Q:X,4,FALSE),"") | H16: =IFERROR(VLOOKUP(Table3[[#This Row],[KELAS]],Q:X,5,FALSE),"") | I16: =IFERROR(VLOOKUP(Table3[[#This Row],[KELAS]],Q:X,6,FALSE),"") | K16: =SUM(Table3[[#This Row],[PENDAFT.]:[SPP*]]) -> 0 | M16: =Table3[[#This Row],[TOTAL]]-Table3[[#This Row],[DISKON*]] -> 0
A17: 11 | E17: =IFERROR(VLOOKUP(Table3[[#This Row],[KELAS]],Q:X,2,FALSE),"") | F17: =IFERROR(VLOOKUP(Table3[[#This Row],[KELAS]],Q:X,3,FALSE),"") | G17: =IFERROR(VLOOKUP(Table3[[#This Row],[KELAS]],Q:X,4,FALSE),"") | H17: =IFERROR(VLOOKUP(Table3[[#This Row],[KELAS]],Q:X,5,FALSE),"") | I17: =IFERROR(VLOOKUP(Table3[[#This Row],[KELAS]],Q:X,6,FALSE),"") | K17: =SUM(Table3[[#This Row],[PENDAFT.]:[SPP*]]) -> 0 | M17: =Table3[[#This Row],[TOTAL]]-Table3[[#This Row],[DISKON*]] -> 0
A18: 12 | E18: =IFERROR(VLOOKUP(Table3[[#This Row],[KELAS]],Q:X,2,FALSE),"") | F18: =IFERROR(VLOOKUP(Table3[[#This Row],[KELAS]],Q:X,3,FALSE),"") | G18: =IFERROR(VLOOKUP(Table3[[#This Row],[KELAS]],Q:X,4,FALSE),"") | H18: =IFERROR(VLOOKUP(Table3[[#This Row],[KELAS]],Q:X,5,FALSE),"") | I18: =IFERROR(VLOOKUP(Table3[[#This Row],[KELAS]],Q:X,6,FALSE),"") | K18: =SUM(Table3[[#This Row],[PENDAFT.]:[SPP*]]) -> 0 | M18: =Table3[[#This Row],[TOTAL]]-Table3[[#This Row],[DISKON*]] -> 0
A19: 13 | E19: =IFERROR(VLOOKUP(Table3[[#This Row],[KELAS]],Q:X,2,FALSE),"") | F19: =IFERROR(VLOOKUP(Table3[[#This Row],[KELAS]],Q:X,3,FALSE),"") | G19: =IFERROR(VLOOKUP(Table3[[#This Row],[KELAS]],Q:X,4,FALSE),"") | H19: =IFERROR(VLOOKUP(Table3[[#This Row],[KELAS]],Q:X,5,FALSE),"") | I19: =IFERROR(VLOOKUP(Table3[[#This Row],[KELAS]],Q:X,6,FALSE),"") | K19: =SUM(Table3[[#This Row],[PENDAFT.]:[SPP*]]) -> 0 | M19: =Table3[[#This Row],[TOTAL]]-Table3[[#This Row],[DISKON*]] -> 0
A20: 14 | E20: =IFERROR(VLOOKUP(Table3[[#This Row],[KELAS]],Q:X,2,FALSE),"") | F20: =IFERROR(VLOOKUP(Table3[[#This Row],[KELAS]],Q:X,3,FALSE),"") | G20: =IFERROR(VLOOKUP(Table3[[#This Row],[KELAS]],Q:X,4,FALSE),"") | H20: =IFERROR(VLOOKUP(Table3[[#This Row],[KELAS]],Q:X,5,FALSE),"") | I20: =IFERROR(VLOOKUP(Table3[[#This Row],[KELAS]],Q:X,6,FALSE),"") | K20: =SUM(Table3[[#This Row],[PENDAFT.]:[SPP*]]) -> 0 | M20: =Table3[[#This Row],[TOTAL]]-Table3[[#This Row],[DISKON*]] -> 0
A21: 15 | E21: =IFERROR(VLOOKUP(Table3[[#This Row],[KELAS]],Q:X,2,FALSE),"") | F21: =IFERROR(VLOOKUP(Table3[[#This Row],[KELAS]],Q:X,3,FALSE),"") | G21: =IFERROR(VLOOKUP(Table3[[#This Row],[KELAS]],Q:X,4,FALSE),"") | H21: =IFERROR(VLOOKUP(Table3[[#This Row],[KELAS]],Q:X,5,FALSE),"") | I21: =IFERROR(VLOOKUP(Table3[[#This Row],[KELAS]],Q:X,6,FALSE),"") | K21: =SUM(Table3[[#This Row],[PENDAFT.]:[SPP*]]) -> 0 | M21: =Table3[[#This Row],[TOTAL]]-Table3[[#This Row],[DISKON*]] -> 0
... A55: 49 | E55: =IFERROR(VLOOKUP(Table3[[#This Row],[KELAS]],Q:X,2,FALSE),"") | F55: =IFERROR(VLOOKUP(Table3[[#This Row],[KELAS]],Q:X,3,FALSE),"") | G55: =IFERROR(VLOOKUP(Table3[[#This Row],[KELAS]],Q:X,4,FALSE),"") | H55: =IFERROR(VLOOKUP(Table3[[#This Row],[KELAS]],Q:X,5,FALSE),"") | I55: =IFERROR(VLOOKUP(Table3[[#This Row],[KELAS]],Q:X,6,FALSE),"") | K55: =SUM(Table3[[#This Row],[PENDAFT.]:[SPP*]]) -> 0 | M55: =Table3[[#This Row],[TOTAL]]-Table3[[#This Row],[DISKON*]] -> 0
A56: 50 | E56: =IFERROR(VLOOKUP(Table3[[#This Row],[KELAS]],Q:X,2,FALSE),"") | F56: =IFERROR(VLOOKUP(Table3[[#This Row],[KELAS]],Q:X,3,FALSE),"") | G56: =IFERROR(VLOOKUP(Table3[[#This Row],[KELAS]],Q:X,4,FALSE),"") | H56: =IFERROR(VLOOKUP(Table3[[#This Row],[KELAS]],Q:X,5,FALSE),"") | I56: =IFERROR(VLOOKUP(Table3[[#This Row],[KELAS]],Q:X,6,FALSE),"") | K56: =SUM(Table3[[#This Row],[PENDAFT.]:[SPP*]]) -> 0 | M56: =Table3[[#This Row],[TOTAL]]-Table3[[#This Row],[DISKON*]] -> 0 | N56: Siblings
A57: 51 | E57: =IFERROR(VLOOKUP(Table3[[#This Row],[KELAS]],Q:X,2,FALSE),"") | F57: =IFERROR(VLOOKUP(Table3[[#This Row],[KELAS]],Q:X,3,FALSE),"") | G57: =IFERROR(VLOOKUP(Table3[[#This Row],[KELAS]],Q:X,4,FALSE),"") | H57: =IFERROR(VLOOKUP(Table3[[#This Row],[KELAS]],Q:X,5,FALSE),"") | I57: =IFERROR(VLOOKUP(Table3[[#This Row],[KELAS]],Q:X,6,FALSE),"") | K57: =SUM(Table3[[#This Row],[PENDAFT.]:[SPP*]]) -> 0 | M57: =Table3[[#This Row],[TOTAL]]-Table3[[#This Row],[DISKON*]] -> 0
A58: 52 | E58: =IFERROR(VLOOKUP(Table3[[#This Row],[KELAS]],Q:X,2,FALSE),"") | F58: =IFERROR(VLOOKUP(Table3[[#This Row],[KELAS]],Q:X,3,FALSE),"") | G58: =IFERROR(VLOOKUP(Table3[[#This Row],[KELAS]],Q:X,4,FALSE),"") | H58: =IFERROR(VLOOKUP(Table3[[#This Row],[KELAS]],Q:X,5,FALSE),"") | I58: =IFERROR(VLOOKUP(Table3[[#This Row],[KELAS]],Q:X,6,FALSE),"") | K58: =SUM(Table3[[#This Row],[PENDAFT.]:[SPP*]]) -> 0 | M58: =Table3[[#This Row],[TOTAL]]-Table3[[#This Row],[DISKON*]] -> 0
A59: 53 | E59: =IFERROR(VLOOKUP(Table3[[#This Row],[KELAS]],Q:X,2,FALSE),"") | F59: =IFERROR(VLOOKUP(Table3[[#This Row],[KELAS]],Q:X,3,FALSE),"") | G59: =IFERROR(VLOOKUP(Table3[[#This Row],[KELAS]],Q:X,4,FALSE),"") | H59: =IFERROR(VLOOKUP(Table3[[#This Row],[KELAS]],Q:X,5,FALSE),"") | I59: =IFERROR(VLOOKUP(Table3[[#This Row],[KELAS]],Q:X,6,FALSE),"") | K59: =SUM(Table3[[#This Row],[PENDAFT.]:[SPP*]]) -> 0 | M59: =Table3[[#This Row],[TOTAL]]-Table3[[#This Row],[DISKON*]] -> 0
A60: 54 | E60: =IFERROR(VLOOKUP(Table3[[#This Row],[KELAS]],Q:X,2,FALSE),"") | F60: =IFERROR(VLOOKUP(Table3[[#This Row],[KELAS]],Q:X,3,FALSE),"") | G60: =IFERROR(VLOOKUP(Table3[[#This Row],[KELAS]],Q:X,4,FALSE),"") | H60: =IFERROR(VLOOKUP(Table3[[#This Row],[KELAS]],Q:X,5,FALSE),"") | I60: =IFERROR(VLOOKUP(Table3[[#This Row],[KELAS]],Q:X,6,FALSE),"") | K60: =SUM(Table3[[#This Row],[PENDAFT.]:[SPP*]]) -> 0 | M60: =Table3[[#This Row],[TOTAL]]-Table3[[#This Row],[DISKON*]] -> 0
A61: 55 | E61: =IFERROR(VLOOKUP(Table3[[#This Row],[KELAS]],Q:X,2,FALSE),"") | F61: =IFERROR(VLOOKUP(Table3[[#This Row],[KELAS]],Q:X,3,FALSE),"") | G61: =IFERROR(VLOOKUP(Table3[[#This Row],[KELAS]],Q:X,4,FALSE),"") | H61: =IFERROR(VLOOKUP(Table3[[#This Row],[KELAS]],Q:X,5,FALSE),"") | I61: =IFERROR(VLOOKUP(Table3[[#This Row],[KELAS]],Q:X,6,FALSE),"") | K61: =SUM(Table3[[#This Row],[PENDAFT.]:[SPP*]]) -> 0 | M61: =Table3[[#This Row],[TOTAL]]-Table3[[#This Row],[DISKON*]] -> 0
A62: 56 | E62: =IFERROR(VLOOKUP(Table3[[#This Row],[KELAS]],Q:X,2,FALSE),"") | F62: =IFERROR(VLOOKUP(Table3[[#This Row],[KELAS]],Q:X,3,FALSE),"") | G62: =IFERROR(VLOOKUP(Table3[[#This Row],[KELAS]],Q:X,4,FALSE),"") | H62: =IFERROR(VLOOKUP(Table3[[#This Row],[KELAS]],Q:X,5,FALSE),"") | I62: =IFERROR(VLOOKUP(Table3[[#This Row],[KELAS]],Q:X,6,FALSE),"") | K62: =SUM(Table3[[#This Row],[PENDAFT.]:[SPP*]]) -> 0 | M62: =Table3[[#This Row],[TOTAL]]-Table3[[#This Row],[DISKON*]] -> 0
A63: 57 | E63: =IFERROR(VLOOKUP(Table3[[#This Row],[KELAS]],Q:X,2,FALSE),"") | F63: =IFERROR(VLOOKUP(Table3[[#This Row],[KELAS]],Q:X,3,FALSE),"") | G63: =IFERROR(VLOOKUP(Table3[[#This Row],[KELAS]],Q:X,4,FALSE),"") | H63: =IFERROR(VLOOKUP(Table3[[#This Row],[KELAS]],Q:X,5,FALSE),"") | I63: =IFERROR(VLOOKUP(Table3[[#This Row],[KELAS]],Q:X,6,FALSE),"") | K63: =SUM(Table3[[#This Row],[PENDAFT.]:[SPP*]]) -> 0 | M63: =Table3[[#This Row],[TOTAL]]-Table3[[#This Row],[DISKON*]] -> 0
A64: 58 | E64: =IFERROR(VLOOKUP(Table3[[#This Row],[KELAS]],Q:X,2,FALSE),"") | F64: =IFERROR(VLOOKUP(Table3[[#This Row],[KELAS]],Q:X,3,FALSE),"") | G64: =IFERROR(VLOOKUP(Table3[[#This Row],[KELAS]],Q:X,4,FALSE),"") | H64: =IFERROR(VLOOKUP(Table3[[#This Row],[KELAS]],Q:X,5,FALSE),"") | I64: =IFERROR(VLOOKUP(Table3[[#This Row],[KELAS]],Q:X,6,FALSE),"") | K64: =SUM(Table3[[#This Row],[PENDAFT.]:[SPP*]]) -> 0 | M64: =Table3[[#This Row],[TOTAL]]-Table3[[#This Row],[DISKON*]] -> 0
A65: 59 | E65: =IFERROR(VLOOKUP(Table3[[#This Row],[KELAS]],Q:X,2,FALSE),"") | F65: =IFERROR(VLOOKUP(Table3[[#This Row],[KELAS]],Q:X,3,FALSE),"") | G65: =IFERROR(VLOOKUP(Table3[[#This Row],[KELAS]],Q:X,4,FALSE),"") | H65: =IFERROR(VLOOKUP(Table3[[#This Row],[KELAS]],Q:X,5,FALSE),"") | I65: =IFERROR(VLOOKUP(Table3[[#This Row],[KELAS]],Q:X,6,FALSE),"") | K65: =SUM(Table3[[#This Row],[PENDAFT.]:[SPP*]]) -> 0 | M65: =Table3[[#This Row],[TOTAL]]-Table3[[#This Row],[DISKON*]] -> 0
A66: 60 | E66: =IFERROR(VLOOKUP(Table3[[#This Row],[KELAS]],Q:X,2,FALSE),"") | F66: =IFERROR(VLOOKUP(Table3[[#This Row],[KELAS]],Q:X,3,FALSE),"") | G66: =IFERROR(VLOOKUP(Table3[[#This Row],[KELAS]],Q:X,4,FALSE),"") | H66: =IFERROR(VLOOKUP(Table3[[#This Row],[KELAS]],Q:X,5,FALSE),"") | I66: =IFERROR(VLOOKUP(Table3[[#This Row],[KELAS]],Q:X,6,FALSE),"") | K66: =SUM(Table3[[#This Row],[PENDAFT.]:[SPP*]]) -> 0 | M66: =Table3[[#This Row],[TOTAL]]-Table3[[#This Row],[DISKON*]] -> 0
A67: 61 | E67: =IFERROR(VLOOKUP(Table3[[#This Row],[KELAS]],Q:X,2,FALSE),"") | F67: =IFERROR(VLOOKUP(Table3[[#This Row],[KELAS]],Q:X,3,FALSE),"") | G67: =IFERROR(VLOOKUP(Table3[[#This Row],[KELAS]],Q:X,4,FALSE),"") | H67: =IFERROR(VLOOKUP(Table3[[#This Row],[KELAS]],Q:X,5,FALSE),"") | I67: =IFERROR(VLOOKUP(Table3[[#This Row],[KELAS]],Q:X,6,FALSE),"") | K67: =SUM(Table3[[#This Row],[PENDAFT.]:[SPP*]]) -> 0 | M67: =Table3[[#This Row],[TOTAL]]-Table3[[#This Row],[DISKON*]] -> 0
A68: 62 | E68: =IFERROR(VLOOKUP(Table3[[#This Row],[KELAS]],Q:X,2,FALSE),"") | F68: =IFERROR(VLOOKUP(Table3[[#This Row],[KELAS]],Q:X,3,FALSE),"") | G68: =IFERROR(VLOOKUP(Table3[[#This Row],[KELAS]],Q:X,4,FALSE),"") | H68: =IFERROR(VLOOKUP(Table3[[#This Row],[KELAS]],Q:X,5,FALSE),"") | I68: =IFERROR(VLOOKUP(Table3[[#This Row],[KELAS]],Q:X,6,FALSE),"") | K68: =SUM(Table3[[#This Row],[PENDAFT.]:[SPP*]]) -> 0 | M68: =Table3[[#This Row],[TOTAL]]-Table3[[#This Row],[DISKON*]] -> 0
... A96: 90 | E96: =IFERROR(VLOOKUP(Table3[[#This Row],[KELAS]],Q:X,2,FALSE),"") | F96: =IFERROR(VLOOKUP(Table3[[#This Row],[KELAS]],Q:X,3,FALSE),"") | G96: =IFERROR(VLOOKUP(Table3[[#This Row],[KELAS]],Q:X,4,FALSE),"") | H96: =IFERROR(VLOOKUP(Table3[[#This Row],[KELAS]],Q:X,5,FALSE),"") | I96: =IFERROR(VLOOKUP(Table3[[#This Row],[KELAS]],Q:X,6,FALSE),"") | K96: =SUM(Table3[[#This Row],[PENDAFT.]:[SPP*]]) -> 0 | M96: =Table3[[#This Row],[TOTAL]]-Table3[[#This Row],[DISKON*]] -> 0
E97: =IFERROR(VLOOKUP(Table3[[#This Row],[KELAS]],Q:X,2,FALSE),"") | F97: =IFERROR(VLOOKUP(Table3[[#This Row],[KELAS]],Q:X,3,FALSE),"") | G97: =IFERROR(VLOOKUP(Table3[[#This Row],[KELAS]],Q:X,4,FALSE),"") | H97: =IFERROR(VLOOKUP(Table3[[#This Row],[KELAS]],Q:X,5,FALSE),"") | I97: =IFERROR(VLOOKUP(Table3[[#This Row],[KELAS]],Q:X,6,FALSE),"") | K97: =SUM(Table3[[#This Row],[PENDAFT.]:[SPP*]]) -> 0 | M97: =Table3[[#This Row],[TOTAL]]-Table3[[#This Row],[DISKON*]] -> 0
E98: =IFERROR(VLOOKUP(Table3[[#This Row],[KELAS]],Q:X,2,FALSE),"") | F98: =IFERROR(VLOOKUP(Table3[[#This Row],[KELAS]],Q:X,3,FALSE),"") | G98: =IFERROR(VLOOKUP(Table3[[#This Row],[KELAS]],Q:X,4,FALSE),"") | H98: =IFERROR(VLOOKUP(Table3[[#This Row],[KELAS]],Q:X,5,FALSE),"") | I98: =IFERROR(VLOOKUP(Table3[[#This Row],[KELAS]],Q:X,6,FALSE),"") | K98: =SUM(Table3[[#This Row],[PENDAFT.]:[SPP*]]) -> 0 | M98: =Table3[[#This Row],[TOTAL]]-Table3[[#This Row],[DISKON*]] -> 0
E99: =IFERROR(VLOOKUP(Table3[[#This Row],[KELAS]],Q:X,2,FALSE),"") | F99: =IFERROR(VLOOKUP(Table3[[#This Row],[KELAS]],Q:X,3,FALSE),"") | G99: =IFERROR(VLOOKUP(Table3[[#This Row],[KELAS]],Q:X,4,FALSE),"") | H99: =IFERROR(VLOOKUP(Table3[[#This Row],[KELAS]],Q:X,5,FALSE),"") | I99: =IFERROR(VLOOKUP(Table3[[#This Row],[KELAS]],Q:X,6,FALSE),"") | K99: =SUM(Table3[[#This Row],[PENDAFT.]:[SPP*]]) -> 0 | M99: =Table3[[#This Row],[TOTAL]]-Table3[[#This Row],[DISKON*]] -> 0
E100: =IFERROR(VLOOKUP(Table3[[#This Row],[KELAS]],Q:X,2,FALSE),"") | F100: =IFERROR(VLOOKUP(Table3[[#This Row],[KELAS]],Q:X,3,FALSE),"") | G100: =IFERROR(VLOOKUP(Table3[[#This Row],[KELAS]],Q:X,4,FALSE),"") | H100: =IFERROR(VLOOKUP(Table3[[#This Row],[KELAS]],Q:X,5,FALSE),"") | I100: =IFERROR(VLOOKUP(Table3[[#This Row],[KELAS]],Q:X,6,FALSE),"") | K100: =SUM(Table3[[#This Row],[PENDAFT.]:[SPP*]]) -> 0 | M100: =Table3[[#This Row],[TOTAL]]-Table3[[#This Row],[DISKON*]] -> 0
E101: =IFERROR(VLOOKUP(Table3[[#This Row],[KELAS]],Q:X,2,FALSE),"") | F101: =IFERROR(VLOOKUP(Table3[[#This Row],[KELAS]],Q:X,3,FALSE),"") | G101: =IFERROR(VLOOKUP(Table3[[#This Row],[KELAS]],Q:X,4,FALSE),"") | H101: =IFERROR(VLOOKUP(Table3[[#This Row],[KELAS]],Q:X,5,FALSE),"") | I101: =IFERROR(VLOOKUP(Table3[[#This Row],[KELAS]],Q:X,6,FALSE),"") | K101: =SUM(Table3[[#This Row],[PENDAFT.]:[SPP*]]) -> 0 | M101: =Table3[[#This Row],[TOTAL]]-Table3[[#This Row],[DISKON*]] -> 0
E102: =IFERROR(VLOOKUP(Table3[[#This Row],[KELAS]],Q:X,2,FALSE),"") | F102: =IFERROR(VLOOKUP(Table3[[#This Row],[KELAS]],Q:X,3,FALSE),"") | G102: =IFERROR(VLOOKUP(Table3[[#This Row],[KELAS]],Q:X,4,FALSE),"") | H102: =IFERROR(VLOOKUP(Table3[[#This Row],[KELAS]],Q:X,5,FALSE),"") | I102: =IFERROR(VLOOKUP(Table3[[#This Row],[KELAS]],Q:X,6,FALSE),"") | K102: =SUM(Table3[[#This Row],[PENDAFT.]:[SPP*]]) -> 0 | M102: =Table3[[#This Row],[TOTAL]]-Table3[[#This Row],[DISKON*]] -> 0
...

Sheet Data Siswa
A1: DATA SISWA DAN ANGSURAN
A2: ="AL MADEENA ISLAMIC SCHOOL "& Cover!A5 -> AL MADEENA ISLAMIC SCHOOL TAHUN AJARAN 2021 - 2022
A3: =Cover!A7 -> PERIODE JULI 2022
A6: NO | B6: ID | C6: NAMA | D6: KELAS | E6: BIAYA NET | F6: PEMBAYARAN | AB6: TOTAL ANGSURAN | AC6: PIUTANG | AD6: STATUS
F7: PENDAFTARAN | H7: GEDUNG | J7: KEGIATAN | L7: SERAGAM | N7: ATK | P7: ANGSURAN SPP 1 | R7: ANGSURAN SPP 2 | T7: ANGSURAN SPP 3 | V7: ANGSURAN SPP 4 | X7: ANGSURAN SPP 5 | Z7: ANGSURAN SPP 6
F8: JUMLAH | G8: TGL | H8: JUMLAH | I8: TGL | J8: JUMLAH | K8: TGL | L8: JUMLAH | M8: TGL | N8: JUMLAH | O8: TGL | P8: JUMLAH | Q8: TGL | R8: JUMLAH | S8: TGL | T8: JUMLAH | U8: TGL | V8: JUMLAH | W8: TGL | X8: JUMLAH | Y8: TGL | Z8: JUMLAH | AA8: TGL
A9: 1 | C9: =IFERROR('Biaya Siswa'!B7,"") -> 0 | D9: =IFERROR(VLOOKUP(C9,'Biaya Siswa'!B:M,3,FALSE),"") | E9: =IFERROR(VLOOKUP(C9,'Biaya Siswa'!B:M,12,FALSE),"") | AB9: =F9+H9+J9+L9+N9+P9+R9+T9+V9+X9+Z9 -> 0 | AC9: =IFERROR(E9-AB9,"")
A10: 2 | C10: =IFERROR('Biaya Siswa'!B8,"") -> 0 | D10: =IFERROR(VLOOKUP(C10,'Biaya Siswa'!B:M,3,FALSE),"") | E10: =IFERROR(VLOOKUP(C10,'Biaya Siswa'!B:M,12,FALSE),"") | AB10: =F10+H10+J10+L10+N10+P10+R10+T10+V10+X10+Z10 -> 0 | AC10: =IFERROR(E10-AB10,"")
A11: 3 | C11: =IFERROR('Biaya Siswa'!B9,"") -> 0 | D11: =IFERROR(VLOOKUP(C11,'Biaya Siswa'!B:M,3,FALSE),"") | E11: =IFERROR(VLOOKUP(C11,'Biaya Siswa'!B:M,12,FALSE),"") | AB11: =F11+H11+J11+L11+N11+P11+R11+T11+V11+X11+Z11 -> 0 | AC11: =IFERROR(E11-AB11,"")
A12: 4 | C12: =IFERROR('Biaya Siswa'!B10,"") -> 0 | D12: =IFERROR(VLOOKUP(C12,'Biaya Siswa'!B:M,3,FALSE),"") | E12: =IFERROR(VLOOKUP(C12,'Biaya Siswa'!B:M,12,FALSE),"") | AB12: =F12+H12+J12+L12+N12+P12+R12+T12+V12+X12+Z12 -> 0 | AC12: =IFERROR(E12-AB12,"")
A13: 5 | C13: =IFERROR('Biaya Siswa'!B11,"") -> 0 | D13: =IFERROR(VLOOKUP(C13,'Biaya Siswa'!B:M,3,FALSE),"") | E13: =IFERROR(VLOOKUP(C13,'Biaya Siswa'!B:M,12,FALSE),"") | AB13: =F13+H13+J13+L13+N13+P13+R13+T13+V13+X13+Z13 -> 0 | AC13: =IFERROR(E13-AB13,"")
A14: 6 | C14: =IFERROR('Biaya Siswa'!B12,"") -> 0 | D14: =IFERROR(VLOOKUP(C14,'Biaya Siswa'!B:M,3,FALSE),"") | E14: =IFERROR(VLOOKUP(C14,'Biaya Siswa'!B:M,12,FALSE),"") | AB14: =F14+H14+J14+L14+N14+P14+R14+T14+V14+X14+Z14 -> 0 | AC14: =IFERROR(E14-AB14,"")
A15: 7 | C15: =IFERROR('Biaya Siswa'!B13,"") -> 0 | D15: =IFERROR(VLOOKUP(C15,'Biaya Siswa'!B:M,3,FALSE),"") | E15: =IFERROR(VLOOKUP(C15,'Biaya Siswa'!B:M,12,FALSE),"") | AB15: =F15+H15+J15+L15+N15+P15+R15+T15+V15+X15+Z15 -> 0 | AC15: =IFERROR(E15-AB15,"")
A16: 8 | C16: =IFERROR('Biaya Siswa'!B14,"") -> 0 | D16: =IFERROR(VLOOKUP(C16,'Biaya Siswa'!B:M,3,FALSE),"") | E16: =IFERROR(VLOOKUP(C16,'Biaya Siswa'!B:M,12,FALSE),"") | AB16: =F16+H16+J16+L16+N16+P16+R16+T16+V16+X16+Z16 -> 0 | AC16: =IFERROR(E16-AB16,"")
A17: 9 | C17: =IFERROR('Biaya Siswa'!B15,"") -> 0 | D17: =IFERROR(VLOOKUP(C17,'Biaya Siswa'!B:M,3,FALSE),"") | E17: =IFERROR(VLOOKUP(C17,'Biaya Siswa'!B:M,12,FALSE),"") | AB17: =F17+H17+J17+L17+N17+P17+R17+T17+V17+X17+Z17 -> 0 | AC17: =IFERROR(E17-AB17,"")
A18: 10 | C18: =IFERROR('Biaya Siswa'!B18,"") -> 0 | D18: =IFERROR(VLOOKUP(C18,'Biaya Siswa'!B:M,3,FALSE),"") | E18: =IFERROR(VLOOKUP(C18,'Biaya Siswa'!B:M,12,FALSE),"") | AB18: =F18+H18+J18+L18+N18+P18+R18+T18+V18+X18+Z18 -> 0 | AC18: =IFERROR(E18-AB18,"")
A19: 11 | C19: =IFERROR('Biaya Siswa'!B19,"") -> 0 | D19: =IFERROR(VLOOKUP(C19,'Biaya Siswa'!B:M,3,FALSE),"") | E19: =IFERROR(VLOOKUP(C19,'Biaya Siswa'!B:M,12,FALSE),"") | AB19: =F19+H19+J19+L19+N19+P19+R19+T19+V19+X19+Z19 -> 0 | AC19: =IFERROR(E19-AB19,"")
A20: 12 | C20: =IFERROR('Biaya Siswa'!B20,"") -> 0 | D20: =IFERROR(VLOOKUP(C20,'Biaya Siswa'!B:M,3,FALSE),"") | E20: =IFERROR(VLOOKUP(C20,'Biaya Siswa'!B:M,12,FALSE),"") | AB20: =F20+H20+J20+L20+N20+P20+R20+T20+V20+X20+Z20 -> 0 | AC20: =IFERROR(E20-AB20,"")
A21: 13 | C21: =IFERROR('Biaya Siswa'!B21,"") -> 0 | D21: =IFERROR(VLOOKUP(C21,'Biaya Siswa'!B:M,3,FALSE),"") | E21: =IFERROR(VLOOKUP(C21,'Biaya Siswa'!B:M,12,FALSE),"") | AB21: =F21+H21+J21+L21+N21+P21+R21+T21+V21+X21+Z21 -> 0 | AC21: =IFERROR(E21-AB21,"") | AE21: 250000
A22: 14 | C22: =IFERROR('Biaya Siswa'!B22,"") -> 0 | D22: =IFERROR(VLOOKUP(C22,'Biaya Siswa'!B:M,3,FALSE),"") | E22: =IFERROR(VLOOKUP(C22,'Biaya Siswa'!B:M,12,FALSE),"") | AB22: =F22+H22+J22+L22+N22+P22+R22+T22+V22+X22+Z22 -> 0 | AC22: =IFERROR(E22-AB22,"")
A23: 15 | C23: =IFERROR('Biaya Siswa'!B23,"") -> 0 | D23: =IFERROR(VLOOKUP(C23,'Biaya Siswa'!B:M,3,FALSE),"") | E23: =IFERROR(VLOOKUP(C23,'Biaya Siswa'!B:M,12,FALSE),"") | AB23: =F23+H23+J23+L23+N23+P23+R23+T23+V23+X23+Z23 -> 0 | AC23: =IFERROR(E23-AB23,"")
A24: 16 | C24: =IFERROR('Biaya Siswa'!B24,"") -> 0 | D24: =IFERROR(VLOOKUP(C24,'Biaya Siswa'!B:M,3,FALSE),"") | E24: =IFERROR(VLOOKUP(C24,'Biaya Siswa'!B:M,12,FALSE),"") | AB24: =F24+H24+J24+L24+N24+P24+R24+T24+V24+X24+Z24 -> 0 | AC24: =IFERROR(E24-AB24,"") | AE24: 50000
A25: 17 | C25: =IFERROR('Biaya Siswa'!B26,"") -> 0 | D25: =IFERROR(VLOOKUP(C25,'Biaya Siswa'!B:M,3,FALSE),"") | E25: =IFERROR(VLOOKUP(C25,'Biaya Siswa'!B:M,12,FALSE),"") | AB25: =F25+H25+J25+L25+N25+P25+R25+T25+V25+X25+Z25 -> 0 | AC25: =IFERROR(E25-AB25,"")
A26: 18 | C26: =IFERROR('Biaya Siswa'!B27,"") -> 0 | D26: =IFERROR(VLOOKUP(C26,'Biaya Siswa'!B:M,3,FALSE),"") | E26: =IFERROR(VLOOKUP(C26,'Biaya Siswa'!B:M,12,FALSE),"") | AB26: =F26+H26+J26+L26+N26+P26+R26+T26+V26+X26+Z26 -> 0 | AC26: =IFERROR(E26-AB26,"")
A27: 19 | C27: =IFERROR('Biaya Siswa'!B28,"") -> 0 | D27: =IFERROR(VLOOKUP(C27,'Biaya Siswa'!B:M,3,FALSE),"") | E27: =IFERROR(VLOOKUP(C27,'Biaya Siswa'!B:M,12,FALSE),"") | AB27: =F27+H27+J27+L27+N27+P27+R27+T27+V27+X27+Z27 -> 0 | AC27: =IFERROR(E27-AB27,"")
A28: 20 | C28: =IFERROR('Biaya Siswa'!B29,"") -> 0 | D28: =IFERROR(VLOOKUP(C28,'Biaya Siswa'!B:M,3,FALSE),"") | E28: =IFERROR(VLOOKUP(C28,'Biaya Siswa'!B:M,12,FALSE),"") | AB28: =F28+H28+J28+L28+N28+P28+R28+T28+V28+X28+Z28 -> 0 | AC28: =IFERROR(E28-AB28,"")
A29: 21 | C29: =IFERROR('Biaya Siswa'!B30,"") -> 0 | D29: =IFERROR(VLOOKUP(C29,'Biaya Siswa'!B:M,3,FALSE),"") | E29: =IFERROR(VLOOKUP(C29,'Biaya Siswa'!B:M,12,FALSE),"") | AB29: =F29+H29+J29+L29+N29+P29+R29+T29+V29+X29+Z29 -> 0 | AC29: =IFERROR(E29-AB29,"")
A30: 22 | C30: =IFERROR('Biaya Siswa'!B31,"") -> 0 | D30: =IFERROR(VLOOKUP(C30,'Biaya Siswa'!B:M,3,FALSE),"") | E30: =IFERROR(VLOOKUP(C30,'Biaya Siswa'!B:M,12,FALSE),"") | AB30: =F30+H30+J30+L30+N30+P30+R30+T30+V30+X30+Z30 -> 0 | AC30: =IFERROR(E30-AB30,"")
A31: 23 | C31: =IFERROR('Biaya Siswa'!B33,"") -> 0 | D31: =IFERROR(VLOOKUP(C31,'Biaya Siswa'!B:M,3,FALSE),"") | E31: =IFERROR(VLOOKUP(C31,'Biaya Siswa'!B:M,12,FALSE),"") | AB31: =F31+H31+J31+L31+N31+P31+R31+T31+V31+X31+Z31 -> 0 | AC31: =IFERROR(E31-AB31,"")
A32: 24 | C32: =IFERROR('Biaya Siswa'!B35,"") -> 0 | D32: =IFERROR(VLOOKUP(C32,'Biaya Siswa'!B:M,3,FALSE),"") | E32: =IFERROR(VLOOKUP(C32,'Biaya Siswa'!B:M,12,FALSE),"") | AB32: =F32+H32+J32+L32+N32+P32+R32+T32+V32+X32+Z32 -> 0 | AC32: =IFERROR(E32-AB32,"")
A33: 25 | C33: =IFERROR('Biaya Siswa'!B37,"") -> 0 | D33: =IFERROR(VLOOKUP(C33,'Biaya Siswa'!B:M,3,FALSE),"") | E33: =IFERROR(VLOOKUP(C33,'Biaya Siswa'!B:M,12,FALSE),"") | AB33: =F33+H33+J33+L33+N33+P33+R33+T33+V33+X33+Z33 -> 0 | AC33: =IFERROR(E33-AB33,"")
A34: 26 | C34: =IFERROR('Biaya Siswa'!B38,"") -> 0 | D34: =IFERROR(VLOOKUP(C34,'Biaya Siswa'!B:M,3,FALSE),"") | E34: =IFERROR(VLOOKUP(C34,'Biaya Siswa'!B:M,12,FALSE),"") | AB34: =F34+H34+J34+L34+N34+P34+R34+T34+V34+X34+Z34 -> 0 | AC34: =IFERROR(E34-AB34,"")
A35: 27 | C35: =IFERROR('Biaya Siswa'!B39,"") -> 0 | D35: =IFERROR(VLOOKUP(C35,'Biaya Siswa'!B:M,3,FALSE),"") | E35: =IFERROR(VLOOKUP(C35,'Biaya Siswa'!B:M,12,FALSE),"") | AB35: =F35+H35+J35+L35+N35+P35+R35+T35+V35+X35+Z35 -> 0 | AC35: =IFERROR(E35-AB35,"")
A36: 28 | C36: =IFERROR('Biaya Siswa'!B40,"") -> 0 | D36: =IFERROR(VLOOKUP(C36,'Biaya Siswa'!B:M,3,FALSE),"") | E36: =IFERROR(VLOOKUP(C36,'Biaya Siswa'!B:M,12,FALSE),"") | AB36: =F36+H36+J36+L36+N36+P36+R36+T36+V36+X36+Z36 -> 0 | AC36: =IFERROR(E36-AB36,"")
A37: 29 | C37: =IFERROR('Biaya Siswa'!B41,"") -> 0 | D37: =IFERROR(VLOOKUP(C37,'Biaya Siswa'!B:M,3,FALSE),"") | E37: =IFERROR(VLOOKUP(C37,'Biaya Siswa'!B:M,12,FALSE),"") | AB37: =F37+H37+J37+L37+N37+P37+R37+T37+V37+X37+Z37 -> 0 | AC37: =IFERROR(E37-AB37,"") | AE37: 50000
A38: 30 | C38: =IFERROR('Biaya Siswa'!B43,"") -> 0 | D38: =IFERROR(VLOOKUP(C38,'Biaya Siswa'!B:M,3,FALSE),"") | E38: =IFERROR(VLOOKUP(C38,'Biaya Siswa'!B:M,12,FALSE),"") | AB38: =F38+H38+J38+L38+N38+P38+R38+T38+V38+X38+Z38 -> 0 | AC38: =IFERROR(E38-AB38,"")
A39: 31 | C39: =IFERROR('Biaya Siswa'!B44,"") -> 0 | D39: =IFERROR(VLOOKUP(C39,'Biaya Siswa'!B:M,3,FALSE),"") | E39: =IFERROR(VLOOKUP(C39,'Biaya Siswa'!B:M,12,FALSE),"") | AB39: =F39+H39+J39+L39+N39+P39+R39+T39+V39+X39+Z39 -> 0 | AC39: =IFERROR(E39-AB39,"")
A40: 32 | C40: =IFERROR('Biaya Siswa'!B45,"") -> 0 | D40: =IFERROR(VLOOKUP(C40,'Biaya Siswa'!B:M,3,FALSE),"") | E40: =IFERROR(VLOOKUP(C40,'Biaya Siswa'!B:M,12,FALSE),"") | AB40: =F40+H40+J40+L40+N40+P40+R40+T40+V40+X40+Z40 -> 0 | AC40: =IFERROR(E40-AB40,"")
A41: 33 | C41: =IFERROR('Biaya Siswa'!B46,"") -> 0 | D41: =IFERROR(VLOOKUP(C41,'Biaya Siswa'!B:M,3,FALSE),"") | E41: =IFERROR(VLOOKUP(C41,'Biaya Siswa'!B:M,12,FALSE),"") | AB41: =F41+H41+J41+L41+N41+P41+R41+T41+V41+X41+Z41 -> 0 | AC41: =IFERROR(E41-AB41,"")
A42: 34 | C42: =IFERROR('Biaya Siswa'!B47,"") -> 0 | D42: =IFERROR(VLOOKUP(C42,'Biaya Siswa'!B:M,3,FALSE),"") | E42: =IFERROR(VLOOKUP(C42,'Biaya Siswa'!B:M,12,FALSE),"") | AB42: =F42+H42+J42+L42+N42+P42+R42+T42+V42+X42+Z42 -> 0 | AC42: =IFERROR(E42-AB42,"")
...

Sheet Rekap Siswa
A1: LAPORAN REKAPITULASI PERTAMBAHAN SISWA
A2: ="PERIODE "&Cover!$N$3&" "&Cover!$P$3 -> PERIODE JULI 2022
A4: ="KANTOR CABANG : "&Cover!A5 -> KANTOR CABANG : TAHUN AJARAN 2021 - 2022
A5: NO | B5: JENJANG PENDIDIKAN | C5: SANDI | D5: JUMLAH SISWA | E5: JUMLAH SISWA | F5: SISWA KELUAR PERIODE SEBELUMNYA | G5: TOTAL SISWA
D6: PERIODE SEBELUMNYA | E6: BULAN LAPORAN
A7: 1 | B7: PLAYGROUP | C7: PG | D7: 0 | E7: 0 | F7: 0 | G7: =SUM(D7:E7) -> 0
A8: 2 | B8: KINDERGARTEN | C8: KG | D8: 0 | E8: 0 | F8: 0 | G8: =SUM(D8:E8) -> 0
A9: JUMLAH TOTAL | D9: =SUM(D7:D8) -> 0 | E9: 0 | F9: =SUM(F7:F8) -> 0 | G9: =SUM(G7:G8) -> 0
F12: =D23&", "&TEXT(E23,"DD/MM/YYYY") -> CIREBON, 18/05/2024 | K12: =CONCATENATE("CIREBON, ",UPPER(TEXT(TODAY(),"d mmmm yyyy"))) -> CIREBON, 18 MAY 2024
B13: MENGETAHUI, | F13: AL MADEENA ISLAMIC SCHOOL CIREBON
B19: =Cover!N7 -> MURDIYONO | F19: =Cover!N8 -> ANITA MERLINA
B20: MANAGER | F20: STAFF KEUANGAN
D23: CIREBON | E23: =TODAY() -> 45430

Sheet Absen siswa
A3: Target : 15 siswa. | E3: Target : 30 siswa. | I3: Target : 30 siswa.
E4: Siswa lama: 7 siswa | I4: Siswa lama : 18
A5: 1 | E5: 1 | I5: 1
A6: 2 | E6: 2 | I6: 2
A7: 3 | E7: 3 | I7: 3
A8: 4 | E8: 4 | I8: 4
A9: 5 | E9: 5 | I9: 5
A10: 6 | E10: 6 | I10: 6
A11: 7 | E11: 7 | I11: 7
A12: 8 | E12: 8 | I12: 8
A13: 9 | E13: 9 | I13: 9
A14: 10 | E14: 10 | I14: 10
A15: 11 | E15: 11 | I15: 11
A16: 12 | E16: 12 | I16: 12
... A19: 15 | E19: 15 | I19: 15
E20: 16 | I20: 16
E21: 17 | I21: 17
E22: 18 | I22: 18
E23: 19 | I23: 19
E24: 20 | I24: 20
E25: 21 | I25: 21
E26: 22 | I26: 22
E27: 23 | I27: 23
E28: 24 | I28: 24
E29: 25 | I29: 25
E30: 26 | I30: 26
E31: 27 | I31: 27
... E34: 30 | I34: 30

Sheet Sheet2
